[2024-05-22 01:00:29,162: INFO: __init__: Welcome to our custom logging]
[2024-05-22 01:00:29,162: INFO: main: Welcome to our custom logging]
[2024-05-24 02:09:39,327: INFO: common: yaml file: config\config.yaml loaded successfully]
[2024-05-24 02:09:39,331: INFO: common: yaml file: params.yaml loaded successfully]
[2024-05-24 02:14:15,901: INFO: common: yaml file: config\config.yaml loaded successfully]
[2024-05-24 02:14:15,904: INFO: common: yaml file: params.yaml loaded successfully]
[2024-05-24 02:14:15,906: INFO: common: created directory at: artifacts]
[2024-05-24 02:15:11,892: INFO: common: yaml file: config\config.yaml loaded successfully]
[2024-05-24 02:15:11,895: INFO: common: yaml file: params.yaml loaded successfully]
[2024-05-24 02:15:11,898: INFO: common: created directory at: artifacts]
[2024-05-24 02:15:11,900: INFO: common: created directory at: artifacts/data_ingestion]
[2024-05-24 02:15:13,465: INFO: 12640755: artifacts/data_ingestion/data.zip download! with following info: 
Server: GitHub.com
Date: Thu, 23 May 2024 18:44:20 GMT
Content-Type: text/html; charset=utf-8
Vary: X-PJAX, X-PJAX-Container, Turbo-Visit, Turbo-Frame, Accept-Encoding, Accept, X-Requested-With
ETag: W/"c9bdfd5fb293b79ed32e32f3409b7281"
Cache-Control: max-age=0, private, must-revalidate
Strict-Transport-Security: max-age=31536000; includeSubdomains; preload
X-Frame-Options: deny
X-Content-Type-Options: nosniff
X-XSS-Protection: 0
Referrer-Policy: no-referrer-when-downgrade
Content-Security-Policy: default-src 'none'; base-uri 'self'; child-src github.com/assets-cdn/worker/ gist.github.com/assets-cdn/worker/; connect-src 'self' uploads.github.com www.githubstatus.com collector.github.com raw.githubusercontent.com api.github.com github-cloud.s3.amazonaws.com github-production-repository-file-5c1aeb.s3.amazonaws.com github-production-upload-manifest-file-7fdce7.s3.amazonaws.com github-production-user-asset-6210df.s3.amazonaws.com api.githubcopilot.com objects-origin.githubusercontent.com copilot-proxy.githubusercontent.com/v1/engines/copilot-codex/completions *.actions.githubusercontent.com wss://*.actions.githubusercontent.com productionresultssa0.blob.core.windows.net/ productionresultssa1.blob.core.windows.net/ productionresultssa2.blob.core.windows.net/ productionresultssa3.blob.core.windows.net/ productionresultssa4.blob.core.windows.net/ productionresultssa5.blob.core.windows.net/ productionresultssa6.blob.core.windows.net/ productionresultssa7.blob.core.windows.net/ productionresultssa8.blob.core.windows.net/ productionresultssa9.blob.core.windows.net/ productionresultssa10.blob.core.windows.net/ productionresultssa11.blob.core.windows.net/ productionresultssa12.blob.core.windows.net/ productionresultssa13.blob.core.windows.net/ productionresultssa14.blob.core.windows.net/ productionresultssa15.blob.core.windows.net/ productionresultssa16.blob.core.windows.net/ productionresultssa17.blob.core.windows.net/ productionresultssa18.blob.core.windows.net/ productionresultssa19.blob.core.windows.net/ github-production-repository-image-32fea6.s3.amazonaws.com github-production-release-asset-2e65be.s3.amazonaws.com insights.github.com wss://alive.github.com; font-src github.githubassets.com; form-action 'self' github.com gist.github.com copilot-workspace.githubnext.com objects-origin.githubusercontent.com; frame-ancestors 'none'; frame-src viewscreen.githubusercontent.com notebooks.githubusercontent.com; img-src 'self' data: github.githubassets.com media.githubusercontent.com camo.githubusercontent.com identicons.github.com avatars.githubusercontent.com github-cloud.s3.amazonaws.com objects.githubusercontent.com secured-user-images.githubusercontent.com/ user-images.githubusercontent.com/ private-user-images.githubusercontent.com opengraph.githubassets.com github-production-user-asset-6210df.s3.amazonaws.com customer-stories-feed.github.com spotlights-feed.github.com objects-origin.githubusercontent.com *.githubusercontent.com; manifest-src 'self'; media-src github.com user-images.githubusercontent.com/ secured-user-images.githubusercontent.com/ private-user-images.githubusercontent.com github-production-user-asset-6210df.s3.amazonaws.com gist.github.com; script-src github.githubassets.com; style-src 'unsafe-inline' github.githubassets.com; upgrade-insecure-requests; worker-src github.com/assets-cdn/worker/ gist.github.com/assets-cdn/worker/
Set-Cookie: _gh_sess=WDWusRynl8VgWCxK%2FgSYP0auH4woj%2Fk%2FHMRL%2F%2BUu3tCOSQa0yHqH%2BUoRbnMFsuUh1EedRlybLOTVszBCBw%2FoW%2F1RxG1YDimVH4sQV1DddZo7c45EdWWAjOPqE5GeFaDZe7PyvsS7TWb%2Bmpx3LF9RVlMInefbZ%2BMcMLXZKVDvPl3NRl2kGkZVh%2B26gUIzu26hx193nfljnmsOoyz2APSgJ4k%2BDiRGHgGukZwcT6n13jfUL%2B%2BP70aLHCt%2BKZx5Pq9p9FdVA9G2pmcIDxx9TlSRnw%3D%3D--76SeLDi2wsxbA4dd--so%2B3POsg0yd5NpUdCj0yBQ%3D%3D; Path=/; HttpOnly; Secure; SameSite=Lax
Set-Cookie: _octo=GH1.1.1393022535.1716489859; Path=/; Domain=github.com; Expires=Fri, 23 May 2025 18:44:19 GMT; Secure; SameSite=Lax
Set-Cookie: logged_in=no; Path=/; Domain=github.com; Expires=Fri, 23 May 2025 18:44:19 GMT; HttpOnly; Secure; SameSite=Lax
Accept-Ranges: bytes
Transfer-Encoding: chunked
X-GitHub-Request-Id: CB1C:3CFC3E:607AAE:674C5F:664F8E83
connection: close

]
[2024-05-24 02:17:10,267: INFO: common: yaml file: config\config.yaml loaded successfully]
[2024-05-24 02:17:10,270: INFO: common: yaml file: params.yaml loaded successfully]
[2024-05-24 02:17:10,271: INFO: common: created directory at: artifacts]
[2024-05-24 02:17:10,273: INFO: common: created directory at: artifacts/data_ingestion]
[2024-05-24 02:17:10,274: INFO: 12640755: File already exists of size:  ~ 145 KB]
[2024-08-11 18:57:05,250: INFO: main: Welcome to our custom logging]
[2024-08-17 18:56:11,051: INFO: main: >>>>>>>>>> stage Data Ingestion stage started <<<<<<<<<<]
[2024-08-17 18:56:11,062: INFO: common: yaml file: config\config.yaml loaded successfully]
[2024-08-17 18:56:11,074: INFO: common: yaml file: params.yaml loaded successfully]
[2024-08-17 18:56:11,075: INFO: common: created directory at: artifacts]
[2024-08-17 18:56:11,076: INFO: common: created directory at: artifacts/data_ingestion]
[2024-08-17 18:56:13,622: INFO: data_ingestion: artifacts/data_ingestion/data.zip download! with following info: 
Server: GitHub.com
Date: Sat, 17 Aug 2024 11:24:53 GMT
Content-Type: text/html; charset=utf-8
Vary: X-PJAX, X-PJAX-Container, Turbo-Visit, Turbo-Frame, Accept-Encoding, Accept, X-Requested-With
ETag: W/"f48733cd7475d4ab6ad7fe936b5a9b94"
Cache-Control: max-age=0, private, must-revalidate
Strict-Transport-Security: max-age=31536000; includeSubdomains; preload
X-Frame-Options: deny
X-Content-Type-Options: nosniff
X-XSS-Protection: 0
Referrer-Policy: no-referrer-when-downgrade
Content-Security-Policy: default-src 'none'; base-uri 'self'; child-src github.com/assets-cdn/worker/ github.com/webpack/ github.com/assets/ gist.github.com/assets-cdn/worker/; connect-src 'self' uploads.github.com www.githubstatus.com collector.github.com raw.githubusercontent.com api.github.com github-cloud.s3.amazonaws.com github-production-repository-file-5c1aeb.s3.amazonaws.com github-production-upload-manifest-file-7fdce7.s3.amazonaws.com github-production-user-asset-6210df.s3.amazonaws.com *.rel.tunnels.api.visualstudio.com wss://*.rel.tunnels.api.visualstudio.com api.githubcopilot.com objects-origin.githubusercontent.com copilot-proxy.githubusercontent.com/v1/engines/github-completion/completions proxy.enterprise.githubcopilot.com/v1/engines/github-completion/completions *.actions.githubusercontent.com wss://*.actions.githubusercontent.com productionresultssa0.blob.core.windows.net/ productionresultssa1.blob.core.windows.net/ productionresultssa2.blob.core.windows.net/ productionresultssa3.blob.core.windows.net/ productionresultssa4.blob.core.windows.net/ productionresultssa5.blob.core.windows.net/ productionresultssa6.blob.core.windows.net/ productionresultssa7.blob.core.windows.net/ productionresultssa8.blob.core.windows.net/ productionresultssa9.blob.core.windows.net/ productionresultssa10.blob.core.windows.net/ productionresultssa11.blob.core.windows.net/ productionresultssa12.blob.core.windows.net/ productionresultssa13.blob.core.windows.net/ productionresultssa14.blob.core.windows.net/ productionresultssa15.blob.core.windows.net/ productionresultssa16.blob.core.windows.net/ productionresultssa17.blob.core.windows.net/ productionresultssa18.blob.core.windows.net/ productionresultssa19.blob.core.windows.net/ github-production-repository-image-32fea6.s3.amazonaws.com github-production-release-asset-2e65be.s3.amazonaws.com insights.github.com wss://alive.github.com; font-src github.githubassets.com; form-action 'self' github.com gist.github.com copilot-workspace.githubnext.com objects-origin.githubusercontent.com; frame-ancestors 'none'; frame-src viewscreen.githubusercontent.com notebooks.githubusercontent.com; img-src 'self' data: blob: github.githubassets.com media.githubusercontent.com camo.githubusercontent.com identicons.github.com avatars.githubusercontent.com github-cloud.s3.amazonaws.com objects.githubusercontent.com secured-user-images.githubusercontent.com/ user-images.githubusercontent.com/ private-user-images.githubusercontent.com opengraph.githubassets.com github-production-user-asset-6210df.s3.amazonaws.com customer-stories-feed.github.com spotlights-feed.github.com objects-origin.githubusercontent.com *.githubusercontent.com; manifest-src 'self'; media-src github.com user-images.githubusercontent.com/ secured-user-images.githubusercontent.com/ private-user-images.githubusercontent.com github-production-user-asset-6210df.s3.amazonaws.com gist.github.com; script-src github.githubassets.com; style-src 'unsafe-inline' github.githubassets.com; upgrade-insecure-requests; worker-src github.com/assets-cdn/worker/ github.com/webpack/ github.com/assets/ gist.github.com/assets-cdn/worker/
Set-Cookie: _gh_sess=v960GSwEPAc0CVyZz%2Bok0oLrd60Z242CeDOVyFHaL5Ve14fg7vHWPLMK8mbHtpN6KVY9UL9%2Frz8VAkkltbymg%2B5WrG8px2JNeN2vkYJQyTy13umbbc38fpiCBS1EKeu80%2Fayr%2FAJEEAPnaxWfAU74lUpkXDmebGHlVRhhiIHH9DwdYKua8BH47%2Fw%2FQaC0stMeU11MdEQ84uX7366PW1YH4Nq%2Ft74hMUhwjlAZD5WhX9585InpTRJ4cFTYOSWLR3%2F8azeUotmbnCT6Yk8tovnBg%3D%3D--3dPEvwGsu37fH%2FFM--UqVYflH5jB5S78F5fHxtnA%3D%3D; Path=/; HttpOnly; Secure; SameSite=Lax
Set-Cookie: _octo=GH1.1.64826642.1723893893; Path=/; Domain=github.com; Expires=Sun, 17 Aug 2025 11:24:53 GMT; Secure; SameSite=Lax
Set-Cookie: logged_in=no; Path=/; Domain=github.com; Expires=Sun, 17 Aug 2025 11:24:53 GMT; HttpOnly; Secure; SameSite=Lax
Accept-Ranges: bytes
Transfer-Encoding: chunked
X-GitHub-Request-Id: EA3F:ADCB1:521AAD:6095BE:66C08885
connection: close

]
[2024-08-17 18:56:13,741: ERROR: main: File is not a zip file]
Traceback (most recent call last):
  File "D:\ML_Projects\Text_Summrizer\Text_Summarizer\main.py", line 10, in <module>
    data_inagestion.main()
  File "d:\ml_projects\text_summrizer\text_summarizer\src\textSummarizer\pipeline\stage_01_data_ingestion.py", line 17, in main
    data_ingestion.extract_zip_file()
  File "d:\ml_projects\text_summrizer\text_summarizer\src\textSummarizer\components\data_ingestion.py", line 38, in extract_zip_file
    with zipfile.ZipFile(self.config.local_data_file, 'r') as zip_ref:
  File "D:\Anaconda\envs\textS\lib\zipfile.py", line 1268, in __init__
    self._RealGetContents()
  File "D:\Anaconda\envs\textS\lib\zipfile.py", line 1335, in _RealGetContents
    raise BadZipFile("File is not a zip file")
zipfile.BadZipFile: File is not a zip file
[2024-08-17 19:38:20,142: INFO: common: yaml file: config\config.yaml loaded successfully]
[2024-08-17 19:38:20,149: INFO: common: yaml file: params.yaml loaded successfully]
[2024-08-17 19:38:20,151: INFO: common: created directory at: artifacts]
[2024-08-19 00:34:19,578: INFO: main: >>>>>>>>>> stage Data Validation stage started <<<<<<<<<<]
[2024-08-19 00:34:19,582: INFO: common: yaml file: config\config.yaml loaded successfully]
[2024-08-19 00:34:19,595: INFO: common: yaml file: params.yaml loaded successfully]
[2024-08-19 00:34:19,596: INFO: common: created directory at: artifacts]
[2024-08-19 00:34:19,596: ERROR: main: 'NoneType' object has no attribute 'root_dir']
Traceback (most recent call last):
  File "D:\ML_Projects\Text_Summrizer\Text_Summarizer\main.py", line 24, in <module>
    data_validation.main()
  File "d:\ml_projects\text_summrizer\text_summarizer\src\textSummarizer\pipeline\stage_02_data_validation.py", line 14, in main
    data_validation_config = config.get_data_validation_config()
  File "d:\ml_projects\text_summrizer\text_summarizer\src\textSummarizer\config\configuration.py", line 38, in get_data_validation_config
    create_directories([config.root_dir])
AttributeError: 'NoneType' object has no attribute 'root_dir'
[2024-08-19 00:36:48,554: INFO: main: >>>>>>>>>> stage Data Validation stage started <<<<<<<<<<]
[2024-08-19 00:36:48,557: INFO: common: yaml file: config\config.yaml loaded successfully]
[2024-08-19 00:36:48,558: INFO: common: yaml file: params.yaml loaded successfully]
[2024-08-19 00:36:48,559: INFO: common: created directory at: artifacts]
[2024-08-19 00:36:48,559: ERROR: main: 'NoneType' object has no attribute 'root_dir']
Traceback (most recent call last):
  File "D:\ML_Projects\Text_Summrizer\Text_Summarizer\main.py", line 24, in <module>
    data_validation.main()
  File "d:\ml_projects\text_summrizer\text_summarizer\src\textSummarizer\pipeline\stage_02_data_validation.py", line 14, in main
    data_validation_config = config.get_data_validation_config()
  File "d:\ml_projects\text_summrizer\text_summarizer\src\textSummarizer\config\configuration.py", line 38, in get_data_validation_config
    create_directories([config.root_dir])
AttributeError: 'NoneType' object has no attribute 'root_dir'
[2024-08-19 00:37:11,300: INFO: main: >>>>>>>>>> stage Data Validation stage started <<<<<<<<<<]
[2024-08-19 00:37:24,642: INFO: common: yaml file: config\config.yaml loaded successfully]
[2024-08-19 00:37:24,647: INFO: common: yaml file: params.yaml loaded successfully]
[2024-08-19 00:37:24,649: INFO: common: created directory at: artifacts]
[2024-08-19 00:37:43,984: ERROR: main: 'NoneType' object has no attribute 'root_dir']
Traceback (most recent call last):
  File "D:\ML_Projects\Text_Summrizer\Text_Summarizer\main.py", line 24, in <module>
    data_validation.main()
  File "d:\ml_projects\text_summrizer\text_summarizer\src\textSummarizer\pipeline\stage_02_data_validation.py", line 14, in main
    data_validation_config = config.get_data_validation_config()
  File "d:\ml_projects\text_summrizer\text_summarizer\src\textSummarizer\config\configuration.py", line 38, in get_data_validation_config
    create_directories([config.root_dir])
AttributeError: 'NoneType' object has no attribute 'root_dir'
[2024-08-19 00:38:34,588: INFO: main: >>>>>>>>>> stage Data Validation stage started <<<<<<<<<<]
[2024-08-19 00:38:41,365: INFO: common: yaml file: config\config.yaml loaded successfully]
[2024-08-19 00:38:41,371: INFO: common: yaml file: params.yaml loaded successfully]
[2024-08-19 00:38:41,373: INFO: common: created directory at: artifacts]
[2024-08-19 00:39:33,152: ERROR: main: 'NoneType' object has no attribute 'root_dir']
Traceback (most recent call last):
  File "D:\ML_Projects\Text_Summrizer\Text_Summarizer\main.py", line 24, in <module>
    data_validation.main()
  File "d:\ml_projects\text_summrizer\text_summarizer\src\textSummarizer\pipeline\stage_02_data_validation.py", line 14, in main
    data_validation_config = config.get_data_validation_config()
  File "d:\ml_projects\text_summrizer\text_summarizer\src\textSummarizer\config\configuration.py", line 38, in get_data_validation_config
    create_directories([config.root_dir])
AttributeError: 'NoneType' object has no attribute 'root_dir'
[2024-08-19 00:50:47,637: INFO: main: >>>>>>>>>> stage Data Validation stage started <<<<<<<<<<]
[2024-08-19 00:50:56,348: INFO: common: yaml file: config\config.yaml loaded successfully]
[2024-08-19 00:50:59,257: INFO: common: yaml file: params.yaml loaded successfully]
[2024-08-19 00:51:03,362: INFO: common: created directory at: artifacts]
[2024-08-19 00:52:09,170: INFO: common: created directory at: artifacts/data_validation]
[2024-08-19 00:53:56,245: ERROR: main: [WinError 3] The system cannot find the path specified: 'artifacts\\data_ingestion\\samsum_dataset']
Traceback (most recent call last):
  File "D:\ML_Projects\Text_Summrizer\Text_Summarizer\main.py", line 24, in <module>
    data_validation.main()
  File "d:\ml_projects\text_summrizer\text_summarizer\src\textSummarizer\pipeline\stage_02_data_validation.py", line 16, in main
    data_validation.validate_all_files_exist()
  File "d:\ml_projects\text_summrizer\text_summarizer\src\textSummarizer\components\data_validation.py", line 30, in validate_all_files_exist
    raise e
  File "d:\ml_projects\text_summrizer\text_summarizer\src\textSummarizer\components\data_validation.py", line 16, in validate_all_files_exist
    all_files = os.listdir(os.path.join('artifacts', 'data_ingestion', 'samsum_dataset'))
FileNotFoundError: [WinError 3] The system cannot find the path specified: 'artifacts\\data_ingestion\\samsum_dataset'
[2024-08-19 01:07:55,594: INFO: main: >>>>>>>>>> stage Data Validation stage started <<<<<<<<<<]
[2024-08-19 01:07:55,597: INFO: common: yaml file: config\config.yaml loaded successfully]
[2024-08-19 01:07:55,598: INFO: common: yaml file: params.yaml loaded successfully]
[2024-08-19 01:07:55,599: INFO: common: created directory at: artifacts]
[2024-08-19 01:07:55,599: INFO: common: created directory at: artifacts/data_validation]
[2024-08-19 01:07:55,601: INFO: main: >>>>>>>>> Stage Data Validation stage completed <<<<<<<

x============x]
[2024-08-20 23:43:43,710: INFO: config: PyTorch version 2.4.0 available.]
[2024-08-20 23:54:11,467: INFO: common: yaml file: config\config.yaml loaded successfully]
[2024-08-20 23:54:11,482: INFO: common: yaml file: params.yaml loaded successfully]
[2024-08-20 23:54:11,484: INFO: common: created directory at: artifacts]
[2024-08-20 23:59:49,767: INFO: common: yaml file: config\config.yaml loaded successfully]
[2024-08-20 23:59:49,769: INFO: common: yaml file: params.yaml loaded successfully]
[2024-08-20 23:59:49,771: INFO: common: created directory at: artifacts]
[2024-08-21 00:06:59,531: INFO: config: PyTorch version 2.4.0 available.]
[2024-08-21 00:07:00,684: INFO: common: yaml file: config\config.yaml loaded successfully]
[2024-08-21 00:07:00,699: INFO: common: yaml file: params.yaml loaded successfully]
[2024-08-21 00:07:00,701: INFO: common: created directory at: artifacts]
[2024-08-21 00:50:42,223: INFO: config: PyTorch version 2.4.0 available.]
[2024-08-21 00:50:43,206: INFO: main: >>>>>>>>>> stage Data Transformation stage started <<<<<<<<<<]
[2024-08-21 00:50:43,211: INFO: common: yaml file: config\config.yaml loaded successfully]
[2024-08-21 00:50:43,221: INFO: common: yaml file: params.yaml loaded successfully]
[2024-08-21 00:50:43,224: INFO: common: created directory at: artifacts]
[2024-08-21 00:50:43,224: INFO: common: created directory at: artifacts/data_transformation]
[2024-08-21 00:50:43,225: ERROR: main: __init__() got an unexpected keyword argument 'data_path']
Traceback (most recent call last):
  File "D:\ML_Projects\Text_Summrizer\Text_Summarizer\main.py", line 38, in <module>
    data_transformation.main()
  File "d:\ml_projects\text_summrizer\text_summarizer\src\textSummarizer\pipeline\stage_03_data_transformation.py", line 14, in main
    data_transformation_config = config.get_data_transformation_config()
  File "d:\ml_projects\text_summrizer\text_summarizer\src\textSummarizer\config\configuration.py", line 57, in get_data_transformation_config
    get_transformation_config = DataTransformationConfig(
TypeError: __init__() got an unexpected keyword argument 'data_path'
[2024-08-21 00:58:49,776: INFO: config: PyTorch version 2.4.0 available.]
[2024-08-21 00:58:50,204: INFO: main: >>>>>>>>>> stage Data Transformation stage started <<<<<<<<<<]
[2024-08-21 00:58:50,208: INFO: common: yaml file: config\config.yaml loaded successfully]
[2024-08-21 00:58:50,210: INFO: common: yaml file: params.yaml loaded successfully]
[2024-08-21 00:58:50,212: INFO: common: created directory at: artifacts]
[2024-08-21 00:58:50,212: INFO: common: created directory at: artifacts/data_transformation]
[2024-08-21 00:59:04,064: INFO: main: >>>>>>>>> Stage Data Transformation stage completed <<<<<<<

x============x]
[2024-08-21 18:04:28,552: INFO: config: PyTorch version 2.4.0 available.]
[2024-08-21 18:23:55,749: INFO: config: PyTorch version 2.4.0 available.]
[2024-08-21 18:23:56,916: INFO: common: yaml file: config\config.yaml loaded successfully]
[2024-08-21 18:23:56,931: INFO: common: yaml file: params.yaml loaded successfully]
[2024-08-21 18:23:56,933: INFO: common: created directory at: artifacts]
[2024-08-21 18:25:12,882: INFO: common: yaml file: config\config.yaml loaded successfully]
[2024-08-21 18:25:12,889: INFO: common: yaml file: params.yaml loaded successfully]
[2024-08-21 18:25:12,891: INFO: common: created directory at: artifacts]
[2024-08-21 18:36:22,548: INFO: common: yaml file: config\config.yaml loaded successfully]
[2024-08-21 18:36:22,553: INFO: common: yaml file: params.yaml loaded successfully]
[2024-08-21 18:36:22,555: INFO: common: created directory at: artifacts]
[2024-08-21 18:40:46,125: INFO: config: PyTorch version 2.4.0 available.]
[2024-08-21 18:41:58,870: INFO: config: PyTorch version 2.4.0 available.]
[2024-08-21 18:43:04,648: INFO: config: PyTorch version 2.4.0 available.]
[2024-08-21 18:43:06,126: INFO: main: >>>>>>>>>> stage Model trainer stage started <<<<<<<<<<]
[2024-08-21 18:43:06,130: INFO: common: yaml file: config\config.yaml loaded successfully]
[2024-08-21 18:43:06,133: INFO: common: yaml file: params.yaml loaded successfully]
[2024-08-21 18:43:06,136: INFO: common: created directory at: artifacts]
[2024-08-21 18:43:06,137: ERROR: main: "'ConfigBox' object has no attribute 'get_model_trainer_config'"]
Traceback (most recent call last):
  File "box\box.py", line 503, in box.box.Box.__getitem__
KeyError: 'get_model_trainer_config'

The above exception was the direct cause of the following exception:

Traceback (most recent call last):
  File "box\box.py", line 536, in box.box.Box.__getattr__
  File "box\box.py", line 524, in box.box.Box.__getitem__
box.exceptions.BoxKeyError: "'get_model_trainer_config'"

During handling of the above exception, another exception occurred:

Traceback (most recent call last):
  File "box\box.py", line 538, in box.box.Box.__getattr__
AttributeError: 'ConfigBox' object has no attribute 'get_model_trainer_config'

The above exception was the direct cause of the following exception:

Traceback (most recent call last):
  File "box\config_box.py", line 28, in box.config_box.ConfigBox.__getattr__
  File "box\box.py", line 552, in box.box.Box.__getattr__
box.exceptions.BoxKeyError: "'ConfigBox' object has no attribute 'get_model_trainer_config'"

During handling of the above exception, another exception occurred:

Traceback (most recent call last):
  File "box\box.py", line 503, in box.box.Box.__getitem__
KeyError: 'get_model_trainer_config'

The above exception was the direct cause of the following exception:

Traceback (most recent call last):
  File "box\box.py", line 536, in box.box.Box.__getattr__
  File "box\box.py", line 524, in box.box.Box.__getitem__
box.exceptions.BoxKeyError: "'get_model_trainer_config'"

During handling of the above exception, another exception occurred:

Traceback (most recent call last):
  File "box\box.py", line 538, in box.box.Box.__getattr__
AttributeError: 'ConfigBox' object has no attribute 'get_model_trainer_config'

The above exception was the direct cause of the following exception:

Traceback (most recent call last):
  File "D:\ML_Projects\Text_Summrizer\Text_Summarizer\main.py", line 51, in <module>
    model_trainer.main()
  File "d:\ml_projects\text_summrizer\text_summarizer\src\textSummarizer\pipeline\stage_04_model_trainer.py", line 14, in main
    model_trainer_config = config.get_model_trainer_config()
  File "d:\ml_projects\text_summrizer\text_summarizer\src\textSummarizer\config\configuration.py", line 68, in get_model_trainer_config
    config = self.config.get_model_trainer_config
  File "box\config_box.py", line 30, in box.config_box.ConfigBox.__getattr__
  File "box\box.py", line 552, in box.box.Box.__getattr__
box.exceptions.BoxKeyError: "'ConfigBox' object has no attribute 'get_model_trainer_config'"
[2024-08-21 18:44:58,119: INFO: config: PyTorch version 2.4.0 available.]
[2024-08-21 18:44:59,394: INFO: main: >>>>>>>>>> stage Model trainer stage started <<<<<<<<<<]
[2024-08-21 18:44:59,398: INFO: common: yaml file: config\config.yaml loaded successfully]
[2024-08-21 18:44:59,402: INFO: common: yaml file: params.yaml loaded successfully]
[2024-08-21 18:44:59,404: INFO: common: created directory at: artifacts]
[2024-08-21 18:44:59,405: ERROR: main: "'ConfigBox' object has no attribute 'get_model_trainer_config'"]
Traceback (most recent call last):
  File "box\box.py", line 503, in box.box.Box.__getitem__
KeyError: 'get_model_trainer_config'

The above exception was the direct cause of the following exception:

Traceback (most recent call last):
  File "box\box.py", line 536, in box.box.Box.__getattr__
  File "box\box.py", line 524, in box.box.Box.__getitem__
box.exceptions.BoxKeyError: "'get_model_trainer_config'"

During handling of the above exception, another exception occurred:

Traceback (most recent call last):
  File "box\box.py", line 538, in box.box.Box.__getattr__
AttributeError: 'ConfigBox' object has no attribute 'get_model_trainer_config'

The above exception was the direct cause of the following exception:

Traceback (most recent call last):
  File "box\config_box.py", line 28, in box.config_box.ConfigBox.__getattr__
  File "box\box.py", line 552, in box.box.Box.__getattr__
box.exceptions.BoxKeyError: "'ConfigBox' object has no attribute 'get_model_trainer_config'"

During handling of the above exception, another exception occurred:

Traceback (most recent call last):
  File "box\box.py", line 503, in box.box.Box.__getitem__
KeyError: 'get_model_trainer_config'

The above exception was the direct cause of the following exception:

Traceback (most recent call last):
  File "box\box.py", line 536, in box.box.Box.__getattr__
  File "box\box.py", line 524, in box.box.Box.__getitem__
box.exceptions.BoxKeyError: "'get_model_trainer_config'"

During handling of the above exception, another exception occurred:

Traceback (most recent call last):
  File "box\box.py", line 538, in box.box.Box.__getattr__
AttributeError: 'ConfigBox' object has no attribute 'get_model_trainer_config'

The above exception was the direct cause of the following exception:

Traceback (most recent call last):
  File "D:\ML_Projects\Text_Summrizer\Text_Summarizer\main.py", line 51, in <module>
    model_trainer.main()
  File "d:\ml_projects\text_summrizer\text_summarizer\src\textSummarizer\pipeline\stage_04_model_trainer.py", line 14, in main
    model_trainer_config = config.get_model_trainer_config()
  File "d:\ml_projects\text_summrizer\text_summarizer\src\textSummarizer\config\configuration.py", line 68, in get_model_trainer_config
    config = self.config.get_model_trainer_config
  File "box\config_box.py", line 30, in box.config_box.ConfigBox.__getattr__
  File "box\box.py", line 552, in box.box.Box.__getattr__
box.exceptions.BoxKeyError: "'ConfigBox' object has no attribute 'get_model_trainer_config'"
[2024-08-21 19:20:30,937: INFO: config: PyTorch version 2.4.0 available.]
[2024-08-21 19:20:32,593: INFO: main: >>>>>>>>>> stage Model trainer stage started <<<<<<<<<<]
[2024-08-21 19:20:32,598: INFO: common: yaml file: config\config.yaml loaded successfully]
[2024-08-21 19:20:32,601: INFO: common: yaml file: params.yaml loaded successfully]
[2024-08-21 19:20:32,605: INFO: common: created directory at: artifacts]
[2024-08-21 19:20:32,605: ERROR: main: "'ConfigBox' object has no attribute 'get_model_trainer_config'"]
Traceback (most recent call last):
  File "box\box.py", line 503, in box.box.Box.__getitem__
KeyError: 'get_model_trainer_config'

The above exception was the direct cause of the following exception:

Traceback (most recent call last):
  File "box\box.py", line 536, in box.box.Box.__getattr__
  File "box\box.py", line 524, in box.box.Box.__getitem__
box.exceptions.BoxKeyError: "'get_model_trainer_config'"

During handling of the above exception, another exception occurred:

Traceback (most recent call last):
  File "box\box.py", line 538, in box.box.Box.__getattr__
AttributeError: 'ConfigBox' object has no attribute 'get_model_trainer_config'

The above exception was the direct cause of the following exception:

Traceback (most recent call last):
  File "box\config_box.py", line 28, in box.config_box.ConfigBox.__getattr__
  File "box\box.py", line 552, in box.box.Box.__getattr__
box.exceptions.BoxKeyError: "'ConfigBox' object has no attribute 'get_model_trainer_config'"

During handling of the above exception, another exception occurred:

Traceback (most recent call last):
  File "box\box.py", line 503, in box.box.Box.__getitem__
KeyError: 'get_model_trainer_config'

The above exception was the direct cause of the following exception:

Traceback (most recent call last):
  File "box\box.py", line 536, in box.box.Box.__getattr__
  File "box\box.py", line 524, in box.box.Box.__getitem__
box.exceptions.BoxKeyError: "'get_model_trainer_config'"

During handling of the above exception, another exception occurred:

Traceback (most recent call last):
  File "box\box.py", line 538, in box.box.Box.__getattr__
AttributeError: 'ConfigBox' object has no attribute 'get_model_trainer_config'

The above exception was the direct cause of the following exception:

Traceback (most recent call last):
  File "D:\ML_Projects\Text_Summrizer\Text_Summarizer\main.py", line 51, in <module>
    model_trainer.main()
  File "d:\ml_projects\text_summrizer\text_summarizer\src\textSummarizer\pipeline\stage_04_model_trainer.py", line 14, in main
    model_trainer_config = config.get_model_trainer_config()
  File "d:\ml_projects\text_summrizer\text_summarizer\src\textSummarizer\config\configuration.py", line 68, in get_model_trainer_config
    config = self.config.get_model_trainer_config()
  File "box\config_box.py", line 30, in box.config_box.ConfigBox.__getattr__
  File "box\box.py", line 552, in box.box.Box.__getattr__
box.exceptions.BoxKeyError: "'ConfigBox' object has no attribute 'get_model_trainer_config'"
[2024-08-21 19:24:23,751: INFO: config: PyTorch version 2.4.0 available.]
[2024-08-21 19:24:25,683: INFO: main: >>>>>>>>>> stage Model trainer stage started <<<<<<<<<<]
[2024-08-21 19:24:25,689: INFO: common: yaml file: config\config.yaml loaded successfully]
[2024-08-21 19:24:25,692: INFO: common: yaml file: params.yaml loaded successfully]
[2024-08-21 19:24:25,695: INFO: common: created directory at: artifacts]
[2024-08-21 19:24:25,695: INFO: common: created directory at: artifacts/model_trainer]
[2024-08-21 19:24:25,696: ERROR: main: "'ConfigBox' object has no attribute 'root_dir'"]
Traceback (most recent call last):
  File "box\box.py", line 503, in box.box.Box.__getitem__
KeyError: 'root_dir'

The above exception was the direct cause of the following exception:

Traceback (most recent call last):
  File "box\box.py", line 536, in box.box.Box.__getattr__
  File "box\box.py", line 524, in box.box.Box.__getitem__
box.exceptions.BoxKeyError: "'root_dir'"

During handling of the above exception, another exception occurred:

Traceback (most recent call last):
  File "box\box.py", line 538, in box.box.Box.__getattr__
AttributeError: 'ConfigBox' object has no attribute 'root_dir'

The above exception was the direct cause of the following exception:

Traceback (most recent call last):
  File "box\config_box.py", line 28, in box.config_box.ConfigBox.__getattr__
  File "box\box.py", line 552, in box.box.Box.__getattr__
box.exceptions.BoxKeyError: "'ConfigBox' object has no attribute 'root_dir'"

During handling of the above exception, another exception occurred:

Traceback (most recent call last):
  File "box\box.py", line 503, in box.box.Box.__getitem__
KeyError: 'root_dir'

The above exception was the direct cause of the following exception:

Traceback (most recent call last):
  File "box\box.py", line 536, in box.box.Box.__getattr__
  File "box\box.py", line 524, in box.box.Box.__getitem__
box.exceptions.BoxKeyError: "'root_dir'"

During handling of the above exception, another exception occurred:

Traceback (most recent call last):
  File "box\box.py", line 538, in box.box.Box.__getattr__
AttributeError: 'ConfigBox' object has no attribute 'root_dir'

The above exception was the direct cause of the following exception:

Traceback (most recent call last):
  File "D:\ML_Projects\Text_Summrizer\Text_Summarizer\main.py", line 51, in <module>
    model_trainer.main()
  File "d:\ml_projects\text_summrizer\text_summarizer\src\textSummarizer\pipeline\stage_04_model_trainer.py", line 14, in main
    model_trainer_config = config.get_model_trainer_config()
  File "d:\ml_projects\text_summrizer\text_summarizer\src\textSummarizer\config\configuration.py", line 74, in get_model_trainer_config
    root_dir = params.root_dir,
  File "box\config_box.py", line 30, in box.config_box.ConfigBox.__getattr__
  File "box\box.py", line 552, in box.box.Box.__getattr__
box.exceptions.BoxKeyError: "'ConfigBox' object has no attribute 'root_dir'"
[2024-08-21 19:26:18,052: INFO: config: PyTorch version 2.4.0 available.]
[2024-08-21 19:26:19,357: INFO: main: >>>>>>>>>> stage Model trainer stage started <<<<<<<<<<]
[2024-08-21 19:26:19,361: INFO: common: yaml file: config\config.yaml loaded successfully]
[2024-08-21 19:26:19,364: INFO: common: yaml file: params.yaml loaded successfully]
[2024-08-21 19:26:19,366: INFO: common: created directory at: artifacts]
[2024-08-21 19:26:19,366: INFO: common: created directory at: artifacts/model_trainer]
[2024-08-21 19:26:19,367: ERROR: main: 'ModelTrainerConfig' object has no attribute 'train']
Traceback (most recent call last):
  File "D:\ML_Projects\Text_Summrizer\Text_Summarizer\main.py", line 51, in <module>
    model_trainer.main()
  File "d:\ml_projects\text_summrizer\text_summarizer\src\textSummarizer\pipeline\stage_04_model_trainer.py", line 16, in main
    model_trainer_config.train()
AttributeError: 'ModelTrainerConfig' object has no attribute 'train'
[2024-08-21 19:30:37,453: INFO: config: PyTorch version 2.4.0 available.]
[2024-08-21 19:30:40,465: INFO: main: >>>>>>>>>> stage Model trainer stage started <<<<<<<<<<]
[2024-08-21 19:30:40,477: INFO: common: yaml file: config\config.yaml loaded successfully]
[2024-08-21 19:30:40,491: INFO: common: yaml file: params.yaml loaded successfully]
[2024-08-21 19:30:40,496: INFO: common: created directory at: artifacts]
[2024-08-21 19:30:40,497: INFO: common: created directory at: artifacts/model_trainer]
[2024-08-21 19:30:40,497: ERROR: main: 'ModelTrainerConfig' object has no attribute 'train']
Traceback (most recent call last):
  File "D:\ML_Projects\Text_Summrizer\Text_Summarizer\main.py", line 51, in <module>
    model_trainer.main()
  File "d:\ml_projects\text_summrizer\text_summarizer\src\textSummarizer\pipeline\stage_04_model_trainer.py", line 16, in main
    model_trainer_config.train()
AttributeError: 'ModelTrainerConfig' object has no attribute 'train'
[2024-08-21 19:34:54,469: INFO: config: PyTorch version 2.4.0 available.]
[2024-08-21 19:34:56,115: INFO: main: >>>>>>>>>> stage Model trainer stage started <<<<<<<<<<]
[2024-08-21 19:34:56,120: INFO: common: yaml file: config\config.yaml loaded successfully]
[2024-08-21 19:34:56,127: INFO: common: yaml file: params.yaml loaded successfully]
[2024-08-21 19:34:56,130: INFO: common: created directory at: artifacts]
[2024-08-21 19:34:56,131: INFO: common: created directory at: artifacts/model_trainer]
[2024-08-21 19:43:34,126: ERROR: main: '>' not supported between instances of 'str' and 'int']
Traceback (most recent call last):
  File "D:\ML_Projects\Text_Summrizer\Text_Summarizer\main.py", line 51, in <module>
    model_trainer.main()
  File "d:\ml_projects\text_summrizer\text_summarizer\src\textSummarizer\pipeline\stage_04_model_trainer.py", line 16, in main
    model_trainer_config.train()
  File "d:\ml_projects\text_summrizer\text_summarizer\src\textSummarizer\components\model_trainer.py", line 25, in train
    trainer_args = TrainingArguments(
  File "<string>", line 131, in __init__
  File "D:\Anaconda\envs\textS\lib\site-packages\transformers\training_args.py", line 1585, in __post_init__
    if self.save_strategy == IntervalStrategy.STEPS and self.save_steps > 1:
TypeError: '>' not supported between instances of 'str' and 'int'
[2024-08-21 19:48:44,942: INFO: config: PyTorch version 2.4.0 available.]
[2024-08-21 19:48:47,434: INFO: main: >>>>>>>>>> stage Model trainer stage started <<<<<<<<<<]
[2024-08-21 19:48:47,450: INFO: common: yaml file: config\config.yaml loaded successfully]
[2024-08-21 19:48:47,466: INFO: common: yaml file: params.yaml loaded successfully]
[2024-08-21 19:48:47,471: INFO: common: created directory at: artifacts]
[2024-08-21 19:48:47,472: INFO: common: created directory at: artifacts/model_trainer]
[2024-08-21 19:49:15,482: ERROR: main: invalid literal for int() with base 10: '1e6']
Traceback (most recent call last):
  File "D:\ML_Projects\Text_Summrizer\Text_Summarizer\main.py", line 51, in <module>
    model_trainer.main()
  File "d:\ml_projects\text_summrizer\text_summarizer\src\textSummarizer\pipeline\stage_04_model_trainer.py", line 16, in main
    model_trainer_config.train()
  File "d:\ml_projects\text_summrizer\text_summarizer\src\textSummarizer\components\model_trainer.py", line 29, in train
    evaluation_strategy = self.config.evaluation_strategy, eval_steps = self.config.eval_steps, save_steps = int(self.config.save_steps),
ValueError: invalid literal for int() with base 10: '1e6'
[2024-08-21 19:51:36,130: INFO: config: PyTorch version 2.4.0 available.]
[2024-08-21 19:51:37,723: INFO: main: >>>>>>>>>> stage Model trainer stage started <<<<<<<<<<]
[2024-08-21 19:51:37,728: INFO: common: yaml file: config\config.yaml loaded successfully]
[2024-08-21 19:51:37,733: INFO: common: yaml file: params.yaml loaded successfully]
[2024-08-21 19:51:37,736: INFO: common: created directory at: artifacts]
[2024-08-21 19:51:37,737: INFO: common: created directory at: artifacts/model_trainer]
[2024-08-21 19:52:04,954: ERROR: main: '>' not supported between instances of 'str' and 'int']
Traceback (most recent call last):
  File "D:\ML_Projects\Text_Summrizer\Text_Summarizer\main.py", line 51, in <module>
    model_trainer.main()
  File "d:\ml_projects\text_summrizer\text_summarizer\src\textSummarizer\pipeline\stage_04_model_trainer.py", line 16, in main
    model_trainer_config.train()
  File "d:\ml_projects\text_summrizer\text_summarizer\src\textSummarizer\components\model_trainer.py", line 26, in train
    trainer_args = TrainingArguments(
  File "<string>", line 131, in __init__
  File "D:\Anaconda\envs\textS\lib\site-packages\transformers\training_args.py", line 1585, in __post_init__
    if self.save_strategy == IntervalStrategy.STEPS and self.save_steps > 1:
TypeError: '>' not supported between instances of 'str' and 'int'
[2024-08-21 19:54:36,242: INFO: config: PyTorch version 2.4.0 available.]
[2024-08-21 19:54:37,925: INFO: main: >>>>>>>>>> stage Model trainer stage started <<<<<<<<<<]
[2024-08-21 19:54:37,934: INFO: common: yaml file: config\config.yaml loaded successfully]
[2024-08-21 19:54:37,941: INFO: common: yaml file: params.yaml loaded successfully]
[2024-08-21 19:54:37,943: INFO: common: created directory at: artifacts]
[2024-08-21 19:54:37,944: INFO: common: created directory at: artifacts/model_trainer]
[2024-08-21 19:55:06,376: ERROR: main: Using the `Trainer` with `PyTorch` requires `accelerate>=0.21.0`: Please run `pip install transformers[torch]` or `pip install accelerate -U`]
Traceback (most recent call last):
  File "D:\ML_Projects\Text_Summrizer\Text_Summarizer\main.py", line 51, in <module>
    model_trainer.main()
  File "d:\ml_projects\text_summrizer\text_summarizer\src\textSummarizer\pipeline\stage_04_model_trainer.py", line 16, in main
    model_trainer_config.train()
  File "d:\ml_projects\text_summrizer\text_summarizer\src\textSummarizer\components\model_trainer.py", line 26, in train
    trainer_args = TrainingArguments(
  File "<string>", line 131, in __init__
  File "D:\Anaconda\envs\textS\lib\site-packages\transformers\training_args.py", line 1730, in __post_init__
    self.device
  File "D:\Anaconda\envs\textS\lib\site-packages\transformers\training_args.py", line 2227, in device
    return self._setup_devices
  File "D:\Anaconda\envs\textS\lib\site-packages\transformers\utils\generic.py", line 60, in __get__
    cached = self.fget(obj)
  File "D:\Anaconda\envs\textS\lib\site-packages\transformers\training_args.py", line 2103, in _setup_devices
    raise ImportError(
ImportError: Using the `Trainer` with `PyTorch` requires `accelerate>=0.21.0`: Please run `pip install transformers[torch]` or `pip install accelerate -U`
[2024-08-21 19:57:58,406: INFO: config: PyTorch version 2.4.0 available.]
[2024-08-21 19:58:00,358: INFO: main: >>>>>>>>>> stage Model trainer stage started <<<<<<<<<<]
[2024-08-21 19:58:00,363: INFO: common: yaml file: config\config.yaml loaded successfully]
[2024-08-21 19:58:00,369: INFO: common: yaml file: params.yaml loaded successfully]
[2024-08-21 19:58:00,372: INFO: common: created directory at: artifacts]
[2024-08-21 19:58:00,372: INFO: common: created directory at: artifacts/model_trainer]
[2024-08-21 19:58:30,381: ERROR: main: No columns in the dataset match the model's forward method signature. The following columns have been ignored: [dialogue, summary, id]. Please check the dataset and model. You may need to set `remove_unused_columns=False` in `TrainingArguments`.]
Traceback (most recent call last):
  File "D:\ML_Projects\Text_Summrizer\Text_Summarizer\main.py", line 51, in <module>
    model_trainer.main()
  File "d:\ml_projects\text_summrizer\text_summarizer\src\textSummarizer\pipeline\stage_04_model_trainer.py", line 16, in main
    model_trainer_config.train()
  File "d:\ml_projects\text_summrizer\text_summarizer\src\textSummarizer\components\model_trainer.py", line 40, in train
    trainer.train()
  File "D:\Anaconda\envs\textS\lib\site-packages\transformers\trainer.py", line 1938, in train
    return inner_training_loop(
  File "D:\Anaconda\envs\textS\lib\site-packages\transformers\trainer.py", line 1967, in _inner_training_loop
    train_dataloader = self.get_train_dataloader()
  File "D:\Anaconda\envs\textS\lib\site-packages\transformers\trainer.py", line 892, in get_train_dataloader
    train_dataset = self._remove_unused_columns(train_dataset, description="training")
  File "D:\Anaconda\envs\textS\lib\site-packages\transformers\trainer.py", line 820, in _remove_unused_columns
    raise ValueError(
ValueError: No columns in the dataset match the model's forward method signature. The following columns have been ignored: [dialogue, summary, id]. Please check the dataset and model. You may need to set `remove_unused_columns=False` in `TrainingArguments`.
[2024-08-22 19:28:28,936: INFO: config: PyTorch version 2.4.0 available.]
[2024-08-22 19:28:32,185: INFO: main: >>>>>>>>>> stage Model trainer stage started <<<<<<<<<<]
[2024-08-22 19:28:32,200: INFO: common: yaml file: config\config.yaml loaded successfully]
[2024-08-22 19:28:32,214: INFO: common: yaml file: params.yaml loaded successfully]
[2024-08-22 19:28:32,218: INFO: common: created directory at: artifacts]
[2024-08-22 19:28:32,218: INFO: common: created directory at: artifacts/model_trainer]
[2024-08-22 19:29:07,536: ERROR: main: No columns in the dataset match the model's forward method signature. The following columns have been ignored: [dialogue, id, summary]. Please check the dataset and model. You may need to set `remove_unused_columns=False` in `TrainingArguments`.]
Traceback (most recent call last):
  File "D:\ML_Projects\Text_Summrizer\Text_Summarizer\main.py", line 51, in <module>
    model_trainer.main()
  File "d:\ml_projects\text_summrizer\text_summarizer\src\textSummarizer\pipeline\stage_04_model_trainer.py", line 16, in main
    model_trainer_config.train()
  File "d:\ml_projects\text_summrizer\text_summarizer\src\textSummarizer\components\model_trainer.py", line 40, in train
    trainer.train()
  File "D:\Anaconda\envs\textS\lib\site-packages\transformers\trainer.py", line 1938, in train
    return inner_training_loop(
  File "D:\Anaconda\envs\textS\lib\site-packages\transformers\trainer.py", line 1967, in _inner_training_loop
    train_dataloader = self.get_train_dataloader()
  File "D:\Anaconda\envs\textS\lib\site-packages\transformers\trainer.py", line 892, in get_train_dataloader
    train_dataset = self._remove_unused_columns(train_dataset, description="training")
  File "D:\Anaconda\envs\textS\lib\site-packages\transformers\trainer.py", line 820, in _remove_unused_columns
    raise ValueError(
ValueError: No columns in the dataset match the model's forward method signature. The following columns have been ignored: [dialogue, id, summary]. Please check the dataset and model. You may need to set `remove_unused_columns=False` in `TrainingArguments`.
[2024-08-22 19:30:29,698: INFO: config: PyTorch version 2.4.0 available.]
[2024-08-22 19:30:31,878: INFO: main: >>>>>>>>>> stage Model trainer stage started <<<<<<<<<<]
[2024-08-22 19:30:31,884: INFO: common: yaml file: config\config.yaml loaded successfully]
[2024-08-22 19:30:31,889: INFO: common: yaml file: params.yaml loaded successfully]
[2024-08-22 19:30:31,892: INFO: common: created directory at: artifacts]
[2024-08-22 19:30:31,893: INFO: common: created directory at: artifacts/model_trainer]
[2024-08-22 19:30:59,250: ERROR: main: __init__() got an unexpected keyword argument 'remove_unused_columns']
Traceback (most recent call last):
  File "D:\ML_Projects\Text_Summrizer\Text_Summarizer\main.py", line 51, in <module>
    model_trainer.main()
  File "d:\ml_projects\text_summrizer\text_summarizer\src\textSummarizer\pipeline\stage_04_model_trainer.py", line 16, in main
    model_trainer_config.train()
  File "d:\ml_projects\text_summrizer\text_summarizer\src\textSummarizer\components\model_trainer.py", line 35, in train
    trainer = Trainer(model = model_pegasus, args = trainer_args,
TypeError: __init__() got an unexpected keyword argument 'remove_unused_columns'
[2024-08-22 19:32:16,024: INFO: config: PyTorch version 2.4.0 available.]
[2024-08-22 19:32:18,318: INFO: main: >>>>>>>>>> stage Model trainer stage started <<<<<<<<<<]
[2024-08-22 19:32:18,323: INFO: common: yaml file: config\config.yaml loaded successfully]
[2024-08-22 19:32:18,328: INFO: common: yaml file: params.yaml loaded successfully]
[2024-08-22 19:32:18,332: INFO: common: created directory at: artifacts]
[2024-08-22 19:32:18,333: INFO: common: created directory at: artifacts/model_trainer]
[2024-08-22 19:32:46,010: ERROR: main: You should supply an encoding or a list of encodings to this method that includes input_ids, but you provided ['id', 'dialogue', 'summary']]
Traceback (most recent call last):
  File "D:\ML_Projects\Text_Summrizer\Text_Summarizer\main.py", line 51, in <module>
    model_trainer.main()
  File "d:\ml_projects\text_summrizer\text_summarizer\src\textSummarizer\pipeline\stage_04_model_trainer.py", line 16, in main
    model_trainer_config.train()
  File "d:\ml_projects\text_summrizer\text_summarizer\src\textSummarizer\components\model_trainer.py", line 40, in train
    trainer.train()
  File "D:\Anaconda\envs\textS\lib\site-packages\transformers\trainer.py", line 1938, in train
    return inner_training_loop(
  File "D:\Anaconda\envs\textS\lib\site-packages\transformers\trainer.py", line 2236, in _inner_training_loop
    for step, inputs in enumerate(epoch_iterator):
  File "D:\Anaconda\envs\textS\lib\site-packages\accelerate\data_loader.py", line 454, in __iter__
    current_batch = next(dataloader_iter)
  File "D:\Anaconda\envs\textS\lib\site-packages\torch\utils\data\dataloader.py", line 630, in __next__
    data = self._next_data()
  File "D:\Anaconda\envs\textS\lib\site-packages\torch\utils\data\dataloader.py", line 673, in _next_data
    data = self._dataset_fetcher.fetch(index)  # may raise StopIteration
  File "D:\Anaconda\envs\textS\lib\site-packages\torch\utils\data\_utils\fetch.py", line 55, in fetch
    return self.collate_fn(data)
  File "D:\Anaconda\envs\textS\lib\site-packages\transformers\data\data_collator.py", line 598, in __call__
    batch = pad_without_fast_tokenizer_warning(
  File "D:\Anaconda\envs\textS\lib\site-packages\transformers\data\data_collator.py", line 66, in pad_without_fast_tokenizer_warning
    padded = tokenizer.pad(*pad_args, **pad_kwargs)
  File "D:\Anaconda\envs\textS\lib\site-packages\transformers\tokenization_utils_base.py", line 3479, in pad
    raise ValueError(
ValueError: You should supply an encoding or a list of encodings to this method that includes input_ids, but you provided ['id', 'dialogue', 'summary']
[2024-08-22 19:35:21,009: INFO: config: PyTorch version 2.4.0 available.]
[2024-08-22 19:35:23,418: INFO: main: >>>>>>>>>> stage Model trainer stage started <<<<<<<<<<]
[2024-08-22 19:35:23,423: INFO: common: yaml file: config\config.yaml loaded successfully]
[2024-08-22 19:35:23,430: INFO: common: yaml file: params.yaml loaded successfully]
[2024-08-22 19:35:23,432: INFO: common: created directory at: artifacts]
[2024-08-22 19:35:23,433: INFO: common: created directory at: artifacts/model_trainer]
[2024-08-22 19:35:48,168: ERROR: main: No columns in the dataset match the model's forward method signature. The following columns have been ignored: [id, dialogue, summary]. Please check the dataset and model. You may need to set `remove_unused_columns=False` in `TrainingArguments`.]
Traceback (most recent call last):
  File "D:\ML_Projects\Text_Summrizer\Text_Summarizer\main.py", line 51, in <module>
    model_trainer.main()
  File "d:\ml_projects\text_summrizer\text_summarizer\src\textSummarizer\pipeline\stage_04_model_trainer.py", line 16, in main
    model_trainer_config.train()
  File "d:\ml_projects\text_summrizer\text_summarizer\src\textSummarizer\components\model_trainer.py", line 40, in train
    trainer.train()
  File "D:\Anaconda\envs\textS\lib\site-packages\transformers\trainer.py", line 1938, in train
    return inner_training_loop(
  File "D:\Anaconda\envs\textS\lib\site-packages\transformers\trainer.py", line 1967, in _inner_training_loop
    train_dataloader = self.get_train_dataloader()
  File "D:\Anaconda\envs\textS\lib\site-packages\transformers\trainer.py", line 892, in get_train_dataloader
    train_dataset = self._remove_unused_columns(train_dataset, description="training")
  File "D:\Anaconda\envs\textS\lib\site-packages\transformers\trainer.py", line 820, in _remove_unused_columns
    raise ValueError(
ValueError: No columns in the dataset match the model's forward method signature. The following columns have been ignored: [id, dialogue, summary]. Please check the dataset and model. You may need to set `remove_unused_columns=False` in `TrainingArguments`.
[2024-08-22 19:36:39,131: INFO: config: PyTorch version 2.4.0 available.]
[2024-08-22 19:36:41,128: INFO: main: >>>>>>>>>> stage Model trainer stage started <<<<<<<<<<]
[2024-08-22 19:36:41,139: INFO: common: yaml file: config\config.yaml loaded successfully]
[2024-08-22 19:36:41,151: INFO: common: yaml file: params.yaml loaded successfully]
[2024-08-22 19:36:41,156: INFO: common: created directory at: artifacts]
[2024-08-22 19:36:41,158: INFO: common: created directory at: artifacts/model_trainer]
[2024-08-22 19:37:08,097: ERROR: main: You should supply an encoding or a list of encodings to this method that includes input_ids, but you provided ['id', 'dialogue', 'summary']]
Traceback (most recent call last):
  File "D:\ML_Projects\Text_Summrizer\Text_Summarizer\main.py", line 51, in <module>
    model_trainer.main()
  File "d:\ml_projects\text_summrizer\text_summarizer\src\textSummarizer\pipeline\stage_04_model_trainer.py", line 16, in main
    model_trainer_config.train()
  File "d:\ml_projects\text_summrizer\text_summarizer\src\textSummarizer\components\model_trainer.py", line 40, in train
    trainer.train()
  File "D:\Anaconda\envs\textS\lib\site-packages\transformers\trainer.py", line 1938, in train
    return inner_training_loop(
  File "D:\Anaconda\envs\textS\lib\site-packages\transformers\trainer.py", line 2236, in _inner_training_loop
    for step, inputs in enumerate(epoch_iterator):
  File "D:\Anaconda\envs\textS\lib\site-packages\accelerate\data_loader.py", line 454, in __iter__
    current_batch = next(dataloader_iter)
  File "D:\Anaconda\envs\textS\lib\site-packages\torch\utils\data\dataloader.py", line 630, in __next__
    data = self._next_data()
  File "D:\Anaconda\envs\textS\lib\site-packages\torch\utils\data\dataloader.py", line 673, in _next_data
    data = self._dataset_fetcher.fetch(index)  # may raise StopIteration
  File "D:\Anaconda\envs\textS\lib\site-packages\torch\utils\data\_utils\fetch.py", line 55, in fetch
    return self.collate_fn(data)
  File "D:\Anaconda\envs\textS\lib\site-packages\transformers\data\data_collator.py", line 598, in __call__
    batch = pad_without_fast_tokenizer_warning(
  File "D:\Anaconda\envs\textS\lib\site-packages\transformers\data\data_collator.py", line 66, in pad_without_fast_tokenizer_warning
    padded = tokenizer.pad(*pad_args, **pad_kwargs)
  File "D:\Anaconda\envs\textS\lib\site-packages\transformers\tokenization_utils_base.py", line 3479, in pad
    raise ValueError(
ValueError: You should supply an encoding or a list of encodings to this method that includes input_ids, but you provided ['id', 'dialogue', 'summary']
[2024-08-22 19:46:28,222: INFO: config: PyTorch version 2.4.0 available.]
[2024-08-22 19:46:30,405: INFO: main: >>>>>>>>>> stage Model trainer stage started <<<<<<<<<<]
[2024-08-22 19:46:30,410: INFO: common: yaml file: config\config.yaml loaded successfully]
[2024-08-22 19:46:30,416: INFO: common: yaml file: params.yaml loaded successfully]
[2024-08-22 19:46:30,417: INFO: common: created directory at: artifacts]
[2024-08-22 19:46:30,418: INFO: common: created directory at: artifacts/model_trainer]
[2024-08-22 19:47:04,505: ERROR: main: You should supply an encoding or a list of encodings to this method that includes input_ids, but you provided ['id', 'dialogue', 'summary']]
Traceback (most recent call last):
  File "D:\ML_Projects\Text_Summrizer\Text_Summarizer\main.py", line 51, in <module>
    model_trainer.main()
  File "d:\ml_projects\text_summrizer\text_summarizer\src\textSummarizer\pipeline\stage_04_model_trainer.py", line 16, in main
    model_trainer_config.train()
  File "d:\ml_projects\text_summrizer\text_summarizer\src\textSummarizer\components\model_trainer.py", line 40, in train
    trainer.train()
  File "D:\Anaconda\envs\textS\lib\site-packages\transformers\trainer.py", line 1938, in train
    return inner_training_loop(
  File "D:\Anaconda\envs\textS\lib\site-packages\transformers\trainer.py", line 2236, in _inner_training_loop
    for step, inputs in enumerate(epoch_iterator):
  File "D:\Anaconda\envs\textS\lib\site-packages\accelerate\data_loader.py", line 454, in __iter__
    current_batch = next(dataloader_iter)
  File "D:\Anaconda\envs\textS\lib\site-packages\torch\utils\data\dataloader.py", line 630, in __next__
    data = self._next_data()
  File "D:\Anaconda\envs\textS\lib\site-packages\torch\utils\data\dataloader.py", line 673, in _next_data
    data = self._dataset_fetcher.fetch(index)  # may raise StopIteration
  File "D:\Anaconda\envs\textS\lib\site-packages\torch\utils\data\_utils\fetch.py", line 55, in fetch
    return self.collate_fn(data)
  File "D:\Anaconda\envs\textS\lib\site-packages\transformers\data\data_collator.py", line 598, in __call__
    batch = pad_without_fast_tokenizer_warning(
  File "D:\Anaconda\envs\textS\lib\site-packages\transformers\data\data_collator.py", line 66, in pad_without_fast_tokenizer_warning
    padded = tokenizer.pad(*pad_args, **pad_kwargs)
  File "D:\Anaconda\envs\textS\lib\site-packages\transformers\tokenization_utils_base.py", line 3479, in pad
    raise ValueError(
ValueError: You should supply an encoding or a list of encodings to this method that includes input_ids, but you provided ['id', 'dialogue', 'summary']
[2024-08-22 19:51:16,612: INFO: config: PyTorch version 2.4.0 available.]
[2024-08-22 19:51:18,886: INFO: main: >>>>>>>>>> stage Data Validation stage started <<<<<<<<<<]
[2024-08-22 19:51:18,891: INFO: common: yaml file: config\config.yaml loaded successfully]
[2024-08-22 19:51:18,898: INFO: common: yaml file: params.yaml loaded successfully]
[2024-08-22 19:51:18,901: INFO: common: created directory at: artifacts]
[2024-08-22 19:51:18,902: INFO: common: created directory at: artifacts/data_validation]
[2024-08-22 19:51:18,905: INFO: main: >>>>>>>>> Stage Data Validation stage completed <<<<<<<

x============x]
[2024-08-22 19:51:18,906: INFO: main: >>>>>>>>>> stage Data Transformation stage started <<<<<<<<<<]
[2024-08-22 19:51:18,911: INFO: common: yaml file: config\config.yaml loaded successfully]
[2024-08-22 19:51:18,915: INFO: common: yaml file: params.yaml loaded successfully]
[2024-08-22 19:51:18,917: INFO: common: created directory at: artifacts]
[2024-08-22 19:51:18,918: INFO: common: created directory at: artifacts/data_transformation]
[2024-08-22 19:51:21,659: INFO: main: >>>>>>>>> Stage Data Transformation stage completed <<<<<<<

x============x]
[2024-08-22 19:51:21,660: INFO: main: >>>>>>>>>> stage Model trainer stage started <<<<<<<<<<]
[2024-08-22 19:51:21,664: INFO: common: yaml file: config\config.yaml loaded successfully]
[2024-08-22 19:51:21,667: INFO: common: yaml file: params.yaml loaded successfully]
[2024-08-22 19:51:21,670: INFO: common: created directory at: artifacts]
[2024-08-22 19:51:21,671: INFO: common: created directory at: artifacts/model_trainer]
[2024-08-22 19:51:48,095: ERROR: main: You should supply an encoding or a list of encodings to this method that includes input_ids, but you provided ['id', 'dialogue', 'summary']]
Traceback (most recent call last):
  File "D:\ML_Projects\Text_Summrizer\Text_Summarizer\main.py", line 51, in <module>
    model_trainer.main()
  File "d:\ml_projects\text_summrizer\text_summarizer\src\textSummarizer\pipeline\stage_04_model_trainer.py", line 16, in main
    model_trainer_config.train()
  File "d:\ml_projects\text_summrizer\text_summarizer\src\textSummarizer\components\model_trainer.py", line 40, in train
    trainer.train()
  File "D:\Anaconda\envs\textS\lib\site-packages\transformers\trainer.py", line 1938, in train
    return inner_training_loop(
  File "D:\Anaconda\envs\textS\lib\site-packages\transformers\trainer.py", line 2236, in _inner_training_loop
    for step, inputs in enumerate(epoch_iterator):
  File "D:\Anaconda\envs\textS\lib\site-packages\accelerate\data_loader.py", line 454, in __iter__
    current_batch = next(dataloader_iter)
  File "D:\Anaconda\envs\textS\lib\site-packages\torch\utils\data\dataloader.py", line 630, in __next__
    data = self._next_data()
  File "D:\Anaconda\envs\textS\lib\site-packages\torch\utils\data\dataloader.py", line 673, in _next_data
    data = self._dataset_fetcher.fetch(index)  # may raise StopIteration
  File "D:\Anaconda\envs\textS\lib\site-packages\torch\utils\data\_utils\fetch.py", line 55, in fetch
    return self.collate_fn(data)
  File "D:\Anaconda\envs\textS\lib\site-packages\transformers\data\data_collator.py", line 598, in __call__
    batch = pad_without_fast_tokenizer_warning(
  File "D:\Anaconda\envs\textS\lib\site-packages\transformers\data\data_collator.py", line 66, in pad_without_fast_tokenizer_warning
    padded = tokenizer.pad(*pad_args, **pad_kwargs)
  File "D:\Anaconda\envs\textS\lib\site-packages\transformers\tokenization_utils_base.py", line 3479, in pad
    raise ValueError(
ValueError: You should supply an encoding or a list of encodings to this method that includes input_ids, but you provided ['id', 'dialogue', 'summary']
[2024-08-23 23:19:26,856: INFO: config: PyTorch version 2.4.0 available.]
[2024-08-24 01:23:11,195: INFO: common: yaml file: config\config.yaml loaded successfully]
[2024-08-24 01:23:11,220: INFO: common: yaml file: params.yaml loaded successfully]
[2024-08-24 01:23:11,223: INFO: common: created directory at: artifacts]
[2024-08-24 01:24:41,292: INFO: common: yaml file: config\config.yaml loaded successfully]
[2024-08-24 01:24:41,297: INFO: common: yaml file: params.yaml loaded successfully]
[2024-08-24 01:24:41,298: INFO: common: created directory at: artifacts]
[2024-08-24 02:00:56,186: INFO: server: Started server process [103528]]
[2024-08-24 02:00:56,188: INFO: on: Waiting for application startup.]
[2024-08-24 02:00:56,189: INFO: on: Application startup complete.]
[2024-08-24 02:00:56,190: INFO: server: Uvicorn running on http://0.0.0.0:8080 (Press CTRL+C to quit)]
[2024-08-24 02:04:00,784: INFO: config: PyTorch version 2.4.0 available.]
[2024-08-31 01:33:51,705: INFO: server: Started server process [108164]]
[2024-08-31 01:33:51,706: INFO: on: Waiting for application startup.]
[2024-08-31 01:33:51,707: INFO: on: Application startup complete.]
[2024-08-31 01:33:51,709: INFO: server: Uvicorn running on http://0.0.0.0:8080 (Press CTRL+C to quit)]
[2024-08-31 01:35:51,769: INFO: server: Shutting down]
[2024-08-31 01:35:51,880: INFO: on: Waiting for application shutdown.]
[2024-08-31 01:35:51,880: INFO: on: Application shutdown complete.]
[2024-08-31 01:35:51,881: INFO: server: Finished server process [108164]]
[2024-08-31 01:36:09,067: INFO: server: Started server process [61140]]
[2024-08-31 01:36:09,068: INFO: on: Waiting for application startup.]
[2024-08-31 01:36:09,069: INFO: on: Application startup complete.]
[2024-08-31 01:36:09,070: INFO: server: Uvicorn running on http://0.0.0.0:8080 (Press CTRL+C to quit)]
[2024-08-31 01:38:05,801: INFO: common: yaml file: config\config.yaml loaded successfully]
[2024-08-31 01:38:05,832: INFO: common: yaml file: params.yaml loaded successfully]
[2024-08-31 01:38:05,836: INFO: common: created directory at: artifacts]
[2024-08-31 01:38:05,838: ERROR: h11_impl: Exception in ASGI application
]
Traceback (most recent call last):
  File "box\box.py", line 503, in box.box.Box.__getitem__
KeyError: 'get_model_evaluation'

The above exception was the direct cause of the following exception:

Traceback (most recent call last):
  File "box\box.py", line 536, in box.box.Box.__getattr__
  File "box\box.py", line 524, in box.box.Box.__getitem__
box.exceptions.BoxKeyError: "'get_model_evaluation'"

During handling of the above exception, another exception occurred:

Traceback (most recent call last):
  File "box\box.py", line 538, in box.box.Box.__getattr__
AttributeError: 'ConfigBox' object has no attribute 'get_model_evaluation'

The above exception was the direct cause of the following exception:

Traceback (most recent call last):
  File "box\config_box.py", line 28, in box.config_box.ConfigBox.__getattr__
  File "box\box.py", line 552, in box.box.Box.__getattr__
box.exceptions.BoxKeyError: "'ConfigBox' object has no attribute 'get_model_evaluation'"

During handling of the above exception, another exception occurred:

Traceback (most recent call last):
  File "box\box.py", line 503, in box.box.Box.__getitem__
KeyError: 'get_model_evaluation'

The above exception was the direct cause of the following exception:

Traceback (most recent call last):
  File "box\box.py", line 536, in box.box.Box.__getattr__
  File "box\box.py", line 524, in box.box.Box.__getitem__
box.exceptions.BoxKeyError: "'get_model_evaluation'"

During handling of the above exception, another exception occurred:

Traceback (most recent call last):
  File "box\box.py", line 538, in box.box.Box.__getattr__
AttributeError: 'ConfigBox' object has no attribute 'get_model_evaluation'

The above exception was the direct cause of the following exception:

Traceback (most recent call last):
  File "D:\Anaconda\envs\textS\lib\site-packages\uvicorn\protocols\http\h11_impl.py", line 404, in run_asgi
    result = await app(  # type: ignore[func-returns-value]
  File "D:\Anaconda\envs\textS\lib\site-packages\uvicorn\middleware\proxy_headers.py", line 78, in __call__
    return await self.app(scope, receive, send)
  File "D:\Anaconda\envs\textS\lib\site-packages\fastapi\applications.py", line 269, in __call__
    await super().__call__(scope, receive, send)
  File "D:\Anaconda\envs\textS\lib\site-packages\starlette\applications.py", line 124, in __call__
    await self.middleware_stack(scope, receive, send)
  File "D:\Anaconda\envs\textS\lib\site-packages\starlette\middleware\errors.py", line 184, in __call__
    raise exc
  File "D:\Anaconda\envs\textS\lib\site-packages\starlette\middleware\errors.py", line 162, in __call__
    await self.app(scope, receive, _send)
  File "D:\Anaconda\envs\textS\lib\site-packages\starlette\exceptions.py", line 93, in __call__
    raise exc
  File "D:\Anaconda\envs\textS\lib\site-packages\starlette\exceptions.py", line 82, in __call__
    await self.app(scope, receive, sender)
  File "D:\Anaconda\envs\textS\lib\site-packages\fastapi\middleware\asyncexitstack.py", line 21, in __call__
    raise e
  File "D:\Anaconda\envs\textS\lib\site-packages\fastapi\middleware\asyncexitstack.py", line 18, in __call__
    await self.app(scope, receive, send)
  File "D:\Anaconda\envs\textS\lib\site-packages\starlette\routing.py", line 670, in __call__
    await route.handle(scope, receive, send)
  File "D:\Anaconda\envs\textS\lib\site-packages\starlette\routing.py", line 266, in handle
    await self.app(scope, receive, send)
  File "D:\Anaconda\envs\textS\lib\site-packages\starlette\routing.py", line 65, in app
    response = await func(request)
  File "D:\Anaconda\envs\textS\lib\site-packages\fastapi\routing.py", line 227, in app
    raw_response = await run_endpoint_function(
  File "D:\Anaconda\envs\textS\lib\site-packages\fastapi\routing.py", line 160, in run_endpoint_function
    return await dependant.call(**values)
  File "D:\ML_Projects\Text_Summrizer\Text_Summarizer\app.py", line 42, in predict_route
    raise e
  File "D:\ML_Projects\Text_Summrizer\Text_Summarizer\app.py", line 38, in predict_route
    obj = PredictionPipeline()
  File "d:\ml_projects\text_summrizer\text_summarizer\src\textSummarizer\pipeline\prediction.py", line 9, in __init__
    self.config = ConfigurationManager().get_model_evaluation_config()
  File "d:\ml_projects\text_summrizer\text_summarizer\src\textSummarizer\config\configuration.py", line 100, in get_model_evaluation_config
    config = self.config.get_model_evaluation
  File "box\config_box.py", line 30, in box.config_box.ConfigBox.__getattr__
  File "box\box.py", line 552, in box.box.Box.__getattr__
box.exceptions.BoxKeyError: "'ConfigBox' object has no attribute 'get_model_evaluation'"
